Workbook
Name Tech1: #REF!
Name Tech2: #REF!
Name Tech3: #REF!
Name Tech4: #REF!
Name Tech5: #REF!
Name Tech6: #REF!
Name Tech7: #REF!
Name Tech8: #REF!

Sheet SE4X Production
B1: Space Empires Production Sheet
B2: Economic Phase | C2: 1 | E2: 2* | G2: 3 | I2: 4* | K2: 5 | M2: 6* | O2: 7 | Q2: 8* | S2: 9 | U2: 10* | W2: 11 | Y2: 12* | AA2: 13 | AC2: 14* | AE2: 15 | AG2: 16* | AI2: 17 | AK2: 18* | AM2: 19 | AO2: 20*
B3: Carry over (max 30) | C3: 0 | E3: =SUM(C25-C26) -> 0 | G3: =SUM(E25-E26) -> 0 | I3: =SUM(G25-G26) -> 0 | K3: =SUM(I25-I26) -> 0 | M3: =SUM(K25-K26) -> 0 | O3: =SUM(M25-M26) -> 0 | Q3: =SUM(O25-O26) -> 0 | S3: =SUM(Q25-Q26) -> 0 | U3: =SUM(S25-S26) -> 0 | W3: =SUM(U25-U26) -> 0 | Y3: =SUM(W25-W26) -> 0 | AA3: =SUM(Y25-Y26) -> 0 | AC3: =SUM(AA25-AA26) -> 0 | AE3: =SUM(AC25-AC26) -> 0 | AG3: =SUM(AE25-AE26) -> 0 | AI3: =SUM(AG25-AG26) -> 0 | AK3: =SUM(AI25-AI26) -> 0 | AM3: =SUM(AK25-AK26) -> 0 | AO3: =SUM(AM25-AM26) -> 0
B4: + Colony CP
B5: + Mineral/Resource Card CP
B6: + MS Pipeline CP
B7: Total CP | C7: =SUM(C3:C6) -> 0 | E7: =SUM(E3:E6) -> 0 | G7: =SUM(G3:G6) -> 0 | I7: =SUM(I3:I6) -> 0 | K7: =SUM(K3:K6) -> 0 | M7: =SUM(M3:M6) -> 0 | O7: =SUM(O3:O6) -> 0 | Q7: =SUM(Q3:Q6) -> 0 | S7: =SUM(S3:S6) -> 0 | U7: =SUM(U3:U6) -> 0 | W7: =SUM(W3:W6) -> 0 | Y7: =SUM(Y3:Y6) -> 0 | AA7: =SUM(AA3:AA6) -> 0 | AC7: =SUM(AC3:AC6) -> 0 | AE7: =SUM(AE3:AE6) -> 0 | AG7: =SUM(AG3:AG6) -> 0 | AI7: =SUM(AI3:AI6) -> 0 | AK7: =SUM(AK3:AK6) -> 0 | AM7: =SUM(AM3:AM6) -> 0 | AO7: =SUM(AO3:AO6) -> 0
B8: - Maintenance | E8: =SUM(C8+C27-C28) -> 0 | G8: =SUM(E8+E27-E28) -> 0 | I8: =SUM(G8+G27-G28) -> 0 | K8: =SUM(I8+I27-I28) -> 0 | M8: =SUM(K8+K27-K28) -> 0 | O8: =SUM(M8+M27-M28) -> 0 | Q8: =SUM(O8+O27-O28) -> 0 | S8: =SUM(Q8+Q27-Q28) -> 0 | U8: =SUM(S8+S27-S28) -> 0 | W8: =SUM(U8+U27-U28) -> 0 | Y8: =SUM(W8+W27-W28) -> 0 | AA8: =SUM(Y8+Y27-Y28) -> 0 | AC8: =SUM(AA8+AA27-AA28) -> 0 | AE8: =SUM(AC8+AC27-AC28) -> 0 | AG8: =SUM(AE8+AE27-AE28) -> 0 | AI8: =SUM(AG8+AG27-AG28) -> 0 | AK8: =SUM(AI8+AI27-AI28) -> 0 | AM8: =SUM(AK8+AK27-AK28) -> 0 | AO8: =SUM(AM8+AM27-AM28) -> 0
B9: - Turn order bid
B10: Subtotal | C10: =SUM(C7-SUM(C8:C9)) -> 0 | E10: =SUM(E7-SUM(E8:E9)) -> 0 | G10: =SUM(G7-SUM(G8:G9)) -> 0 | I10: =SUM(I7-SUM(I8:I9)) -> 0 | K10: =SUM(K7-SUM(K8:K9)) -> 0 | M10: =SUM(M7-SUM(M8:M9)) -> 0 | O10: =SUM(O7-SUM(O8:O9)) -> 0 | Q10: =SUM(Q7-SUM(Q8:Q9)) -> 0 | S10: =SUM(S7-SUM(S8:S9)) -> 0 | U10: =SUM(U7-SUM(U8:U9)) -> 0 | W10: =SUM(W7-SUM(W8:W9)) -> 0 | Y10: =SUM(Y7-SUM(Y8:Y9)) -> 0 | AA10: =SUM(AA7-SUM(AA8:AA9)) -> 0 | AC10: =SUM(AC7-SUM(AC8:AC9)) -> 0 | AE10: =SUM(AE7-SUM(AE8:AE9)) -> 0 | AG10: =SUM(AG7-SUM(AG8:AG9)) -> 0 | AI10: =SUM(AI7-SUM(AI8:AI9)) -> 0 | AK10: =SUM(AK7-SUM(AK8:AK9)) -> 0 | AM10: =SUM(AM7-SUM(AM8:AM9)) -> 0 | AO10: =SUM(AO7-SUM(AO8:AO9)) -> 0
B11: -Technology Spending
B16: - Ship Spending
B22: * draw 2 crew cards and keep 1
B23: 1 troop per 3 unblockaded colonies
B25: Remaining CP | C25: =SUM(C10-SUM(C11:C24)) -> 0 | E25: =SUM(E10-SUM(E11:E24)) -> 0 | G25: =SUM(G10-SUM(G11:G24)) -> 0 | I25: =SUM(I10-SUM(I11:I24)) -> 0 | K25: =SUM(K10-SUM(K11:K24)) -> 0 | M25: =SUM(M10-SUM(M11:M24)) -> 0 | O25: =SUM(O10-SUM(O11:O24)) -> 0 | Q25: =SUM(Q10-SUM(Q11:Q24)) -> 0 | S25: =SUM(S10-SUM(S11:S24)) -> 0 | U25: =SUM(U10-SUM(U11:U24)) -> 0 | W25: =SUM(W10-SUM(W11:W24)) -> 0 | Y25: =SUM(Y10-SUM(Y11:Y24)) -> 0 | AA25: =SUM(AA10-SUM(AA11:AA24)) -> 0 | AC25: =SUM(AC10-SUM(AC11:AC24)) -> 0 | AE25: =SUM(AE10-SUM(AE11:AE24)) -> 0 | AG25: =SUM(AG10-SUM(AG11:AG24)) -> 0 | AI25: =SUM(AI10-SUM(AI11:AI24)) -> 0 | AK25: =SUM(AK10-SUM(AK11:AK24)) -> 0 | AM25: =SUM(AM10-SUM(AM11:AM24)) -> 0 | AO25: =SUM(AO10-SUM(AO11:AO24)) -> 0
B26: - CP spent on upgrades
B27: Maintenance Inc (buys)
B28: Maintenance Dec (losses)
B30: Technology | C30: Start | E30: Current | G30: Level CP (Cost)
B31: Ship Size | C31: 1 | E31: 1 | G31: 2 (10) | I31: 3 (15) | K31: 4 (20) | M31: 5 (20) | O31: 6 (20) | Q31: 7 (30) | T31: FALSE | V31: Alternate Empire
B32: Attack | C32: 0 | E32: 0 | G32: 1 (20) | I32: 2 (30) | K32: 3 (25) | M32: 4 (10)
B33: Defense | C33: 0 | E33: 0 | G33: 1 (20) | I33: 2 (30) | K33: 3 (25)
B34: Tactics | C34: 0 | E34: 0 | G34: 1 (15) | I34: 2 (15) | K34: 3 (15)
B35: Move | C35: 1 | E35: 1 | G35: 2 (20) | I35: 3 (25) | K35: 4 (25) | M35: 5 (25) | O35: 6 (20) | Q35: 7 (20)
B36: Fighters | C36: 0 | E36: 0 | G36: 1 (25) | I36: 2 (20) | K36: 3 (25) | M36: 4 (25)
B37: Point Defense | C37: 0 | E37: 0 | G37: 1 (20) | I37: 2 (20) | K37: 3 (20)
B38: Ship Yards | C38: 1 | E38: 1 | G38: 2 (20) | I38: 3 (25)
B39: Terraforming | C39: 0 | E39: 0 | G39: 1 (20) | I39: 2 (25)
B40: Exploration | C40: 0 | E40: 0 | G40: 1 (15) | I40: 2 (15)
B41: Cloaking | C41: 0 | E41: 0 | G41: 1 (30) | I41: 2 (30)
B42: Scanners | C42: 0 | E42: 0 | G42: 1 (20) | I42: 2 (20)
B43: Mines | C43: 0 | E43: 0 | G43: 1 (30)
B44: Mine Sweep | C44: 0 | E44: 0 | G44: 1 (10) | I44: 2 (15) | K44: 3 (20)
B45: Advanced Rules
B46: Ground Combat | C46: 1 | E46: 1 | G46: 2 (10) | I46: 3 (25)
B47: Advanced Construction | C47: 0 | E47: 0 | G47: 1 (10) | I47: 2 (10) | K47: 3 (10)
B48: Anti-Replicator | C48: 0 | E48: 0 | G48: 1 (10)
B49: Military Academy | C49: 0 | E49: 0 | G49: 1 (10) | I49: 2 (20)
B50: Boarding | C50: 0 | E50: 0 | G50: 1 (20) | I50: 2 (25)
B51: Security Forces | C51: 0 | E51: 0 | G51: 1 (15) | I51: 2 (15)
...

Sheet Ship Technology
F1: Ship Technology Sheet
F2: Group | G2: Attack | H2: Defense | I2: Tactics | J2: Move | K2: React | L2: Other | P2: Special Ability | Q2: Experience
F3: SY | G3: =IF('SE4X Production'!$E$32<=1,'SE4X Production'!$E$32,0) -> 0 | H3: =IF('SE4X Production'!$E$33<=1,'SE4X Production'!$E$33,0) -> 0 | I3: ='SE4X Production'!$E$34 -> 0 | L3: Ship Yard | M3: ='SE4X Production'!$E38 -> 1 | R3: TRUE
F4: =IF('SE4X Production'!$E$47>=1," AdvBase"," Base") -> Base | G4: =IF('SE4X Production'!$E$32<=3,'SE4X Production'!$E$32,0) -> 0 | H4: =IF('SE4X Production'!$E$33<=3,'SE4X Production'!$E$33,0) -> 0 | I4: ='SE4X Production'!$E$34 -> 0 | L4: =IF('SE4X Production'!$E$47>=1," Exploration","") | M4: =IF('SE4X Production'!$E$47>=1,'SE4X Production'!$E$40,"") | N4: =IF('SE4X Production'!$E$47>=1," Scanners","") | O4: =IF('SE4X Production'!$E$47>=1,'SE4X Production'!$E$42,"") | R4: FALSE
F5: SB | G5: ='SE4X Production'!$E$32 -> 0 | H5: ='SE4X Production'!$E$33 -> 0 | I5: ='SE4X Production'!$E$34 -> 0 | L5: Exploration | M5: ='SE4X Production'!$E$40 -> 0 | N5: Ship Yard | O5: ='SE4X Production'!$E38 -> 1 | R5: FALSE
F6: DSN | G6: =IF('SE4X Production'!$E$32<=3,'SE4X Production'!$E$32,0) -> 0 | H6: =IF('SE4X Production'!$E$33<=3,'SE4X Production'!$E$33,0) -> 0 | I6: ='SE4X Production'!$E$34 -> 0 | R6: FALSE
A7: FALSE | D7: FALSE | F7: =IF('SE4X Production'!$E$47>=3," AdvFlag"," Flag") -> Flag | G7: =IF(A7,IF(D7,MIN('SE4X Production'!$E$32,3),G7),0) -> 0 | H7: =IF(A7,IF(D7,MIN('SE4X Production'!$E$33,3),H7),0) -> 0 | I7: =IF(A7,IF(D7,MIN('SE4X Production'!$E$34,3),I7),0) -> 0 | J7: =IF(A7,IF(D7,MIN('SE4X Production'!$E$35,7),J7),1) -> 1 | K7: =IF(A7,IF(D7,IF(J7>=4,"+",""),K7),"") | L7: Exploration | M7: =IF(A7,IF(D7,MIN('SE4X Production'!$E$40,2),M7),0) -> 0 | N7: =IF(NOT('SE4X Production'!$T$31)," Fast 1",IF(ISTEXT(P27),P27,"")) -> Fast 1 | O7: =IF(A7,IF(D7,IF(NOT('SE4X Production'!$T$31),MIN('SE4X Production'!$E$54,1),1),O7),0) -> 0 | S7: Point Defense
A8: FALSE | D8: FALSE | F8: SC #1 | G8: =IF(A8,IF(D8,MIN('SE4X Production'!$E$32,1),G8),0) -> 0 | H8: =IF(A8,IF(D8,MIN('SE4X Production'!$E$33,1),H8),0) -> 0 | I8: =IF(A8,IF(D8,MIN('SE4X Production'!$E$34,3),I8),0) -> 0 | J8: =IF(A8,IF(D8,MIN('SE4X Production'!$E$35,7),J8),1) -> 1 | K8: =IF(A8,IF(D8,IF(J8>=3,"+",""),K8),"") | L8: Point Defense | M8: =IF(A8,IF(D8,MIN('SE4X Production'!$E$37,3),M8),0) -> 0 | R8: TRUE | S8: Scanners
A9: FALSE | D9: FALSE | F9: SC #2 | G9: =IF(A9,IF(D9,MIN('SE4X Production'!$E$32,1),G9),0) -> 0 | H9: =IF(A9,IF(D9,MIN('SE4X Production'!$E$33,1),H9),0) -> 0 | I9: =IF(A9,IF(D9,MIN('SE4X Production'!$E$34,3),I9),0) -> 0 | J9: =IF(A9,IF(D9,MIN('SE4X Production'!$E$35,7),J9),1) -> 1 | K9: =IF(A9,IF(D9,IF(J9>=3,"+",""),K9),"") | L9: Point Defense | M9: =IF(A9,IF(D9,MIN('SE4X Production'!$E$37,3),M9),0) -> 0 | R9: FALSE | S9: Exploration
A10: FALSE | D10: FALSE | F10: SC #3 | G10: =IF(A10,IF(D10,MIN('SE4X Production'!$E$32,1),G10),0) -> 0 | H10: =IF(A10,IF(D10,MIN('SE4X Production'!$E$33,1),H10),0) -> 0 | I10: =IF(A10,IF(D10,MIN('SE4X Production'!$E$34,3),I10),0) -> 0 | J10: =IF(A10,IF(D10,MIN('SE4X Production'!$E$35,7),J10),1) -> 1 | K10: =IF(A10,IF(D10,IF(J10>=3,"+",""),K10),"") | L10: Point Defense | M10: =IF(A10,IF(D10,MIN('SE4X Production'!$E$37,3),M10),0) -> 0 | R10: FALSE | S10: Fast 1
A11: FALSE | D11: FALSE | F11: SC #4 | G11: =IF(A11,IF(D11,MIN('SE4X Production'!$E$32,1),G11),0) -> 0 | H11: =IF(A11,IF(D11,MIN('SE4X Production'!$E$33,1),H11),0) -> 0 | I11: =IF(A11,IF(D11,MIN('SE4X Production'!$E$34,3),I11),0) -> 0 | J11: =IF(A11,IF(D11,MIN('SE4X Production'!$E$35,7),J11),1) -> 1 | K11: =IF(A11,IF(D11,IF(J11>=3,"+",""),K11),"") | L11: Point Defense | M11: =IF(A11,IF(D11,MIN('SE4X Production'!$E$37,3),M11),0) -> 0 | R11: FALSE | S11: Mini-Fighter Bay
A12: FALSE | D12: FALSE | F12: SC #5 | G12: =IF(A12,IF(D12,MIN('SE4X Production'!$E$32,1),G12),0) -> 0 | H12: =IF(A12,IF(D12,MIN('SE4X Production'!$E$33,1),H12),0) -> 0 | I12: =IF(A12,IF(D12,MIN('SE4X Production'!$E$34,3),I12),0) -> 0 | J12: =IF(A12,IF(D12,MIN('SE4X Production'!$E$35,7),J12),1) -> 1 | K12: =IF(A12,IF(D12,IF(J12>=3,"+",""),K12),"") | L12: Point Defense | M12: =IF(A12,IF(D12,MIN('SE4X Production'!$E$37,3),M12),0) -> 0 | R12: FALSE | S12: Anti-Sensor Hull
A13: FALSE | D13: FALSE | F13: SC #6 | G13: =IF(A13,IF(D13,MIN('SE4X Production'!$E$32,1),G13),0) -> 0 | H13: =IF(A13,IF(D13,MIN('SE4X Production'!$E$33,1),H13),0) -> 0 | I13: =IF(A13,IF(D13,MIN('SE4X Production'!$E$34,3),I13),0) -> 0 | J13: =IF(A13,IF(D13,MIN('SE4X Production'!$E$35,7),J13),1) -> 1 | K13: =IF(A13,IF(D13,IF(J13>=3,"+",""),K13),"") | L13: Point Defense | M13: =IF(A13,IF(D13,MIN('SE4X Production'!$E$37,3),M13),0) -> 0 | R13: FALSE | S13: Shield Projector
A14: FALSE | D14: FALSE | F14: SCX #7 | G14: =IF(A14,IF(D14,MIN('SE4X Production'!$E$32,1),G14),0) -> 0 | H14: =IF(A14,IF(D14,MIN('SE4X Production'!$E$33,1),H14),0) -> 0 | I14: =IF(A14,IF(D14,MIN('SE4X Production'!$E$34,3),I14),0) -> 0 | J14: =IF(A14,IF(D14,MIN('SE4X Production'!$E$35+3,7),J14),1) -> 1 | K14: =IF(A14,IF(D14,IF(J14>=3,"+",""),K14),"") | L14: Point Defense | M14: =IF(A14,IF(D14,MIN('SE4X Production'!$E$37,3),M14),0) -> 0 | R14: FALSE | S14: Design Weakness
A15: FALSE | D15: FALSE | F15: DD #1 | G15: =IF(A15,IF(D15,IF('SE4X Production'!$E$47<1,MIN('SE4X Production'!$E$32,1),MIN('SE4X Production'!$E$32,2)),G15),0) -> 0 | H15: =IF(A15,IF(D15,IF('SE4X Production'!$E$47<1,MIN('SE4X Production'!$E$33,1),MIN('SE4X Production'!$E$33,2)),H15),0) -> 0 | I15: =IF(A15,IF(D15,MIN('SE4X Production'!$E$34,3),I15),0) -> 0 | J15: =IF(A15,IF(D15,MIN('SE4X Production'!$E$35,7),J15),1) -> 1 | K15: =IF(A15,IF(D15,IF(J15>=3,"+",""),K15),"") | L15: Scanners | M15: =IF(A15,IF(D15,MIN('SE4X Production'!$E$42,2),M15),0) -> 0 | N15: =IF(A15,IF(D15,IF('SE4X Production'!$E$47>=1," Fast 2",""),N15),"") | O15: =IF(A15,IF(D15,IF('SE4X Production'!$E$47>=1,IF('SE4X Production'!$E$54>=2,2,0),""),O15),"") | P15: =IF(A15,IF(D15,IF('SE4X Production'!$E$47>=1,"Heavy Wayheads",""),P15),"") | R15: FALSE | S15: Construction Bay
A16: FALSE | D16: FALSE | F16: DD #2 | G16: =IF(A16,IF(D16,IF('SE4X Production'!$E$47<1,MIN('SE4X Production'!$E$32,1),MIN('SE4X Production'!$E$32,2)),G16),0) -> 0 | H16: =IF(A16,IF(D16,IF('SE4X Production'!$E$47<1,MIN('SE4X Production'!$E$33,1),MIN('SE4X Production'!$E$33,2)),H16),0) -> 0 | I16: =IF(A16,IF(D16,MIN('SE4X Production'!$E$34,3),I16),0) -> 0 | J16: =IF(A16,IF(D16,MIN('SE4X Production'!$E$35,7),J16),1) -> 1 | K16: =IF(A16,IF(D16,IF(J16>=3,"+",""),K16),"") | L16: Scanners | M16: =IF(A16,IF(D16,MIN('SE4X Production'!$E$42,2),M16),0) -> 0 | N16: =IF(A16,IF(D16,IF('SE4X Production'!$E$47>=1," Fast 2",""),N16),"") | O16: =IF(A16,IF(D16,IF('SE4X Production'!$E$47>=1,IF('SE4X Production'!$E$54>=2,2,0),""),O16),"") | P16: =IF(A16,IF(D16,IF('SE4X Production'!$E$47>=1,"Heavy Wayheads",""),P16),"") | R16: FALSE | S16: Tractor Beam
A17: FALSE | D17: FALSE | F17: DD #3 | G17: =IF(A17,IF(D17,IF('SE4X Production'!$E$47<1,MIN('SE4X Production'!$E$32,1),MIN('SE4X Production'!$E$32,2)),G17),0) -> 0 | H17: =IF(A17,IF(D17,IF('SE4X Production'!$E$47<1,MIN('SE4X Production'!$E$33,1),MIN('SE4X Production'!$E$33,2)),H17),0) -> 0 | I17: =IF(A17,IF(D17,MIN('SE4X Production'!$E$34,3),I17),0) -> 0 | J17: =IF(A17,IF(D17,MIN('SE4X Production'!$E$35,7),J17),1) -> 1 | K17: =IF(A17,IF(D17,IF(J17>=3,"+",""),K17),"") | L17: Scanners | M17: =IF(A17,IF(D17,MIN('SE4X Production'!$E$42,2),M17),0) -> 0 | N17: =IF(A17,IF(D17,IF('SE4X Production'!$E$47>=1," Fast 2",""),N17),"") | O17: =IF(A17,IF(D17,IF('SE4X Production'!$E$47>=1,IF('SE4X Production'!$E$54>=2,2,0),""),O17),"") | P17: =IF(A17,IF(D17,IF('SE4X Production'!$E$47>=1,"Heavy Wayheads",""),P17),"") | R17: FALSE | S17: Warp Gates
A18: FALSE | D18: FALSE | F18: DD #4 | G18: =IF(A18,IF(D18,IF('SE4X Production'!$E$47<1,MIN('SE4X Production'!$E$32,1),MIN('SE4X Production'!$E$32,2)),G18),0) -> 0 | H18: =IF(A18,IF(D18,IF('SE4X Production'!$E$47<1,MIN('SE4X Production'!$E$33,1),MIN('SE4X Production'!$E$33,2)),H18),0) -> 0 | I18: =IF(A18,IF(D18,MIN('SE4X Production'!$E$34,3),I18),0) -> 0 | J18: =IF(A18,IF(D18,MIN('SE4X Production'!$E$35,7),J18),1) -> 1 | K18: =IF(A18,IF(D18,IF(J18>=3,"+",""),K18),"") | L18: Scanners | M18: =IF(A18,IF(D18,MIN('SE4X Production'!$E$42,2),M18),0) -> 0 | N18: =IF(A18,IF(D18,IF('SE4X Production'!$E$47>=1," Fast 2",""),N18),"") | O18: =IF(A18,IF(D18,IF('SE4X Production'!$E$47>=1,IF('SE4X Production'!$E$54>=2,2,0),""),O18),"") | P18: =IF(A18,IF(D18,IF('SE4X Production'!$E$47>=1,"Heavy Wayheads",""),P18),"") | R18: FALSE | S18: Second Salvo
A19: FALSE | D19: FALSE | F19: DD #5 | G19: =IF(A19,IF(D19,IF('SE4X Production'!$E$47<1,MIN('SE4X Production'!$E$32,1),MIN('SE4X Production'!$E$32,2)),G19),0) -> 0 | H19: =IF(A19,IF(D19,IF('SE4X Production'!$E$47<1,MIN('SE4X Production'!$E$33,1),MIN('SE4X Production'!$E$33,2)),H19),0) -> 0 | I19: =IF(A19,IF(D19,MIN('SE4X Production'!$E$34,3),I19),0) -> 0 | J19: =IF(A19,IF(D19,MIN('SE4X Production'!$E$35,7),J19),1) -> 1 | K19: =IF(A19,IF(D19,IF(J19>=3,"+",""),K19),"") | L19: Scanners | M19: =IF(A19,IF(D19,MIN('SE4X Production'!$E$42,2),M19),0) -> 0 | N19: =IF(A19,IF(D19,IF('SE4X Production'!$E$47>=1," Fast 2",""),N19),"") | O19: =IF(A19,IF(D19,IF('SE4X Production'!$E$47>=1,IF('SE4X Production'!$E$54>=2,2,0),""),O19),"") | P19: =IF(A19,IF(D19,IF('SE4X Production'!$E$47>=1,"Heavy Wayheads",""),P19),"") | R19: FALSE | S19: Heavy Warheads
A20: FALSE | D20: FALSE | F20: DD #6 | G20: =IF(A20,IF(D20,IF('SE4X Production'!$E$47<1,MIN('SE4X Production'!$E$32,1),MIN('SE4X Production'!$E$32,2)),G20),0) -> 0 | H20: =IF(A20,IF(D20,IF('SE4X Production'!$E$47<1,MIN('SE4X Production'!$E$33,1),MIN('SE4X Production'!$E$33,2)),H20),0) -> 0 | I20: =IF(A20,IF(D20,MIN('SE4X Production'!$E$34,3),I20),0) -> 0 | J20: =IF(A20,IF(D20,MIN('SE4X Production'!$E$35,7),J20),1) -> 1 | K20: =IF(A20,IF(D20,IF(J20>=3,"+",""),K20),"") | L20: Scanners | M20: =IF(A20,IF(D20,MIN('SE4X Production'!$E$42,2),M20),0) -> 0 | N20: =IF(A20,IF(D20,IF('SE4X Production'!$E$47>=1," Fast 2",""),N20),"") | O20: =IF(A20,IF(D20,IF('SE4X Production'!$E$47>=1,IF('SE4X Production'!$E$54>=2,2,0),""),O20),"") | P20: =IF(A20,IF(D20,IF('SE4X Production'!$E$47>=1,"Heavy Wayheads",""),P20),"") | R20: FALSE
A21: FALSE | D21: FALSE | F21: CA #1 | G21: =IF(A21,IF(D21,MIN('SE4X Production'!$E$32,2),G21),0) -> 0 | H21: =IF(A21,IF(D21,MIN('SE4X Production'!$E$33,2),H21),0) -> 0 | I21: =IF(A21,IF(D21,MIN('SE4X Production'!$E$34,3),I21),0) -> 0 | J21: =IF(A21,IF(D21,MIN('SE4X Production'!$E$35,7),J21),1) -> 1 | K21: =IF(A21,IF(D21,IF(J21>=3,"+",""),K21),"") | L21: Exploration | M21: =IF(A21,IF(D21,MIN('SE4X Production'!$E$40,2),M21),0) -> 0 | N21: Jammer | O21: =IF(A21,IF(D21,MIN('SE4X Production'!$E$53,2),O21),0) -> 0 | R21: FALSE
A22: FALSE | D22: FALSE | F22: CA #2 | G22: =IF(A22,IF(D22,MIN('SE4X Production'!$E$32,2),G22),0) -> 0 | H22: =IF(A22,IF(D22,MIN('SE4X Production'!$E$33,2),H22),0) -> 0 | I22: =IF(A22,IF(D22,MIN('SE4X Production'!$E$34,3),I22),0) -> 0 | J22: =IF(A22,IF(D22,MIN('SE4X Production'!$E$35,7),J22),1) -> 1 | K22: =IF(A22,IF(D22,IF(J22>=3,"+",""),K22),"") | L22: Exploration | M22: =IF(A22,IF(D22,MIN('SE4X Production'!$E$40,2),M22),0) -> 0 | N22: Jammer | O22: =IF(A22,IF(D22,MIN('SE4X Production'!$E$53,2),O22),0) -> 0 | R22: FALSE
A23: FALSE | D23: FALSE | F23: CA #3 | G23: =IF(A23,IF(D23,MIN('SE4X Production'!$E$32,2),G23),0) -> 0 | H23: =IF(A23,IF(D23,MIN('SE4X Production'!$E$33,2),H23),0) -> 0 | I23: =IF(A23,IF(D23,MIN('SE4X Production'!$E$34,3),I23),0) -> 0 | J23: =IF(A23,IF(D23,MIN('SE4X Production'!$E$35,7),J23),1) -> 1 | K23: =IF(A23,IF(D23,IF(J23>=3,"+",""),K23),"") | L23: Exploration | M23: =IF(A23,IF(D23,MIN('SE4X Production'!$E$40,2),M23),0) -> 0 | N23: Jammer | O23: =IF(A23,IF(D23,MIN('SE4X Production'!$E$53,2),O23),0) -> 0 | R23: FALSE
A24: FALSE | D24: FALSE | F24: CA #4 | G24: =IF(A24,IF(D24,MIN('SE4X Production'!$E$32,2),G24),0) -> 0 | H24: =IF(A24,IF(D24,MIN('SE4X Production'!$E$33,2),H24),0) -> 0 | I24: =IF(A24,IF(D24,MIN('SE4X Production'!$E$34,3),I24),0) -> 0 | J24: =IF(A24,IF(D24,MIN('SE4X Production'!$E$35,7),J24),1) -> 1 | K24: =IF(A24,IF(D24,IF(J24>=3,"+",""),K24),"") | L24: Exploration | M24: =IF(A24,IF(D24,MIN('SE4X Production'!$E$40,2),M24),0) -> 0 | N24: Jammer | O24: =IF(A24,IF(D24,MIN('SE4X Production'!$E$53,2),O24),0) -> 0 | R24: FALSE
A25: FALSE | D25: FALSE | F25: CA #5 | G25: =IF(A25,IF(D25,MIN('SE4X Production'!$E$32,2),G25),0) -> 0 | H25: =IF(A25,IF(D25,MIN('SE4X Production'!$E$33,2),H25),0) -> 0 | I25: =IF(A25,IF(D25,MIN('SE4X Production'!$E$34,3),I25),0) -> 0 | J25: =IF(A25,IF(D25,MIN('SE4X Production'!$E$35,7),J25),1) -> 1 | K25: =IF(A25,IF(D25,IF(J25>=3,"+",""),K25),"") | L25: Exploration | M25: =IF(A25,IF(D25,MIN('SE4X Production'!$E$40,2),M25),0) -> 0 | N25: Jammer | O25: =IF(A25,IF(D25,MIN('SE4X Production'!$E$53,2),O25),0) -> 0 | R25: FALSE
A26: FALSE | D26: FALSE | F26: CA #6 | G26: =IF(A26,IF(D26,MIN('SE4X Production'!$E$32,2),G26),0) -> 0 | H26: =IF(A26,IF(D26,MIN('SE4X Production'!$E$33,2),H26),0) -> 0 | I26: =IF(A26,IF(D26,MIN('SE4X Production'!$E$34,3),I26),0) -> 0 | J26: =IF(A26,IF(D26,MIN('SE4X Production'!$E$35,7),J26),1) -> 1 | K26: =IF(A26,IF(D26,IF(J26>=3,"+",""),K26),"") | L26: Exploration | M26: =IF(A26,IF(D26,MIN('SE4X Production'!$E$40,2),M26),0) -> 0 | N26: Jammer | O26: =IF(A26,IF(D26,MIN('SE4X Production'!$E$53,2),O26),0) -> 0 | R26: FALSE
A27: FALSE | D27: FALSE | F27: BC #1 | G27: =IF(A27,IF(D27,MIN('SE4X Production'!$E$32,2),G27),0) -> 0 | H27: =IF(A27,IF(D27,MIN('SE4X Production'!$E$33,2),H27),0) -> 0 | I27: =IF(A27,IF(D27,MIN('SE4X Production'!$E$34,3),I27),0) -> 0 | J27: =IF(A27,IF(D27,MIN('SE4X Production'!$E$35,7),J27),1) -> 1 | K27: =IF(A27,IF(D27,IF(J27>=4,"+",""),K27),"") | L27: Fast 1 | M27: =IF(A27,IF(D27,MIN('SE4X Production'!$E$54,1),M27),0) -> 0 | R27: FALSE | S27: Fast 1
A28: FALSE | D28: FALSE | F28: BC #2 | G28: =IF(A28,IF(D28,MIN('SE4X Production'!$E$32,2),G28),0) -> 0 | H28: =IF(A28,IF(D28,MIN('SE4X Production'!$E$33,2),H28),0) -> 0 | I28: =IF(A28,IF(D28,MIN('SE4X Production'!$E$34,3),I28),0) -> 0 | J28: =IF(A28,IF(D28,MIN('SE4X Production'!$E$35,7),J28),1) -> 1 | K28: =IF(A28,IF(D28,IF(J28>=4,"+",""),K28),"") | L28: Fast 1 | M28: =IF(A28,IF(D28,MIN('SE4X Production'!$E$54,1),M28),0) -> 0 | R28: FALSE | S28: Space Pilgrim
A29: FALSE | D29: FALSE | F29: BC #3 | G29: =IF(A29,IF(D29,MIN('SE4X Production'!$E$32,2),G29),0) -> 0 | H29: =IF(A29,IF(D29,MIN('SE4X Production'!$E$33,2),H29),0) -> 0 | I29: =IF(A29,IF(D29,MIN('SE4X Production'!$E$34,3),I29),0) -> 0 | J29: =IF(A29,IF(D29,MIN('SE4X Production'!$E$35,7),J29),1) -> 1 | K29: =IF(A29,IF(D29,IF(J29>=4,"+",""),K29),"") | L29: Fast 1 | M29: =IF(A29,IF(D29,MIN('SE4X Production'!$E$54,1),M29),0) -> 0 | R29: FALSE | S29: Second Salvo
A30: FALSE | D30: FALSE | F30: BC #4 | G30: =IF(A30,IF(D30,MIN('SE4X Production'!$E$32,2),G30),0) -> 0 | H30: =IF(A30,IF(D30,MIN('SE4X Production'!$E$33,2),H30),0) -> 0 | I30: =IF(A30,IF(D30,MIN('SE4X Production'!$E$34,3),I30),0) -> 0 | J30: =IF(A30,IF(D30,MIN('SE4X Production'!$E$35,7),J30),1) -> 1 | K30: =IF(A30,IF(D30,IF(J30>=4,"+",""),K30),"") | L30: Fast 1 | M30: =IF(A30,IF(D30,MIN('SE4X Production'!$E$54,1),M30),0) -> 0 | R30: FALSE | S30: Anti-Sensor Hull
A31: FALSE | D31: FALSE | F31: BC #5 | G31: =IF(A31,IF(D31,MIN('SE4X Production'!$E$32,2),G31),0) -> 0 | H31: =IF(A31,IF(D31,MIN('SE4X Production'!$E$33,2),H31),0) -> 0 | I31: =IF(A31,IF(D31,MIN('SE4X Production'!$E$34,3),I31),0) -> 0 | J31: =IF(A31,IF(D31,MIN('SE4X Production'!$E$35,7),J31),1) -> 1 | K31: =IF(A31,IF(D31,IF(J31>=4,"+",""),K31),"") | L31: Fast 1 | M31: =IF(A31,IF(D31,MIN('SE4X Production'!$E$54,1),M31),0) -> 0 | R31: FALSE | S31: +1 Att vs. HS >=2
A32: FALSE | D32: FALSE | F32: BC #6 | G32: =IF(A32,IF(D32,MIN('SE4X Production'!$E$32,2),G32),0) -> 0 | H32: =IF(A32,IF(D32,MIN('SE4X Production'!$E$33,2),H32),0) -> 0 | I32: =IF(A32,IF(D32,MIN('SE4X Production'!$E$34,3),I32),0) -> 0 | J32: =IF(A32,IF(D32,MIN('SE4X Production'!$E$35,7),J32),1) -> 1 | K32: =IF(A32,IF(D32,IF(J32>=4,"+",""),K32),"") | L32: Fast 1 | M32: =IF(A32,IF(D32,MIN('SE4X Production'!$E$54,1),M32),0) -> 0 | R32: FALSE | S32: +1 Att vs. HS <=1
A33: FALSE | D33: FALSE | F33: BB #1 | G33: =IF(A33,IF(D33,MIN('SE4X Production'!$E$32,3),G33),0) -> 0 | H33: =IF(A33,IF(D33,MIN('SE4X Production'!$E$33,3),H33),0) -> 0 | I33: =IF(A33,IF(D33,MIN('SE4X Production'!$E$34,3),I33),0) -> 0 | J33: =IF(A33,IF(D33,MIN('SE4X Production'!$E$35,7),J33),1) -> 1 | K33: =IF(A33,IF(D33,IF(J33>=5,"+",""),K33),"") | L33: =IF(A33,IF(D33,IF('SE4X Production'!$E$47>=1," Tractor Beam",""),L33),"") | M33: =IF(A33,IF(D33,IF('SE4X Production'!$E$47>=1,'SE4X Production'!$E$55,""),M33),"") | R33: FALSE | S33: +1 Def vs. HS >=2
A34: FALSE | D34: FALSE | F34: BB #2 | G34: =IF(A34,IF(D34,MIN('SE4X Production'!$E$32,3),G34),0) -> 0 | H34: =IF(A34,IF(D34,MIN('SE4X Production'!$E$33,3),H34),0) -> 0 | I34: =IF(A34,IF(D34,MIN('SE4X Production'!$E$34,3),I34),0) -> 0 | J34: =IF(A34,IF(D34,MIN('SE4X Production'!$E$35,7),J34),1) -> 1 | K34: =IF(A34,IF(D34,IF(J34>=5,"+",""),K34),"") | L34: =IF(A34,IF(D34,IF('SE4X Production'!$E$47>=1," Tractor Beam",""),L34),"") | M34: =IF(A34,IF(D34,IF('SE4X Production'!$E$47>=1,'SE4X Production'!$E$55,""),M34),"") | R34: FALSE | S34: +1 Def vs. HS <=1
A35: FALSE | D35: FALSE | F35: BB #3 | G35: =IF(A35,IF(D35,MIN('SE4X Production'!$E$32,3),G35),0) -> 0 | H35: =IF(A35,IF(D35,MIN('SE4X Production'!$E$33,3),H35),0) -> 0 | I35: =IF(A35,IF(D35,MIN('SE4X Production'!$E$34,3),I35),0) -> 0 | J35: =IF(A35,IF(D35,MIN('SE4X Production'!$E$35,7),J35),1) -> 1 | K35: =IF(A35,IF(D35,IF(J35>=5,"+",""),K35),"") | L35: =IF(A35,IF(D35,IF('SE4X Production'!$E$47>=1," Tractor Beam",""),L35),"") | M35: =IF(A35,IF(D35,IF('SE4X Production'!$E$47>=1,'SE4X Production'!$E$55,""),M35),"") | S35: Tractor Beam
A36: FALSE | D36: FALSE | F36: BB #4 | G36: =IF(A36,IF(D36,MIN('SE4X Production'!$E$32,3),G36),0) -> 0 | H36: =IF(A36,IF(D36,MIN('SE4X Production'!$E$33,3),H36),0) -> 0 | I36: =IF(A36,IF(D36,MIN('SE4X Production'!$E$34,3),I36),0) -> 0 | J36: =IF(A36,IF(D36,MIN('SE4X Production'!$E$35,7),J36),1) -> 1 | K36: =IF(A36,IF(D36,IF(J36>=5,"+",""),K36),"") | L36: =IF(A36,IF(D36,IF('SE4X Production'!$E$47>=1," Tractor Beam",""),L36),"") | M36: =IF(A36,IF(D36,IF('SE4X Production'!$E$47>=1,'SE4X Production'!$E$55,""),M36),"") | S36: Shield Projector
A37: FALSE | D37: FALSE | F37: BB #5 | G37: =IF(A37,IF(D37,MIN('SE4X Production'!$E$32,3),G37),0) -> 0 | H37: =IF(A37,IF(D37,MIN('SE4X Production'!$E$33,3),H37),0) -> 0 | I37: =IF(A37,IF(D37,MIN('SE4X Production'!$E$34,3),I37),0) -> 0 | J37: =IF(A37,IF(D37,MIN('SE4X Production'!$E$35,7),J37),1) -> 1 | K37: =IF(A37,IF(D37,IF(J37>=5,"+",""),K37),"") | L37: =IF(A37,IF(D37,IF('SE4X Production'!$E$47>=1," Tractor Beam",""),L37),"") | M37: =IF(A37,IF(D37,IF('SE4X Production'!$E$47>=1,'SE4X Production'!$E$55,""),M37),"") | S37: Advanced Munitions
A38: FALSE | D38: FALSE | F38: BB #6 | G38: =IF(A38,IF(D38,MIN('SE4X Production'!$E$32,3),G38),0) -> 0 | H38: =IF(A38,IF(D38,MIN('SE4X Production'!$E$33,3),H38),0) -> 0 | I38: =IF(A38,IF(D38,MIN('SE4X Production'!$E$34,3),I38),0) -> 0 | J38: =IF(A38,IF(D38,MIN('SE4X Production'!$E$35,7),J38),1) -> 1 | K38: =IF(A38,IF(D38,IF(J38>=5,"+",""),K38),"") | L38: =IF(A38,IF(D38,IF('SE4X Production'!$E$47>=1," Tractor Beam",""),L38),"") | M38: =IF(A38,IF(D38,IF('SE4X Production'!$E$47>=1,'SE4X Production'!$E$55,""),M38),"") | S38: Construction Efficiency
A39: FALSE | D39: FALSE | F39: DN #1 | G39: =IF(A39,IF(D39,MIN('SE4X Production'!$E$32,3),G39),0) -> 0 | H39: =IF(A39,IF(D39,MIN('SE4X Production'!$E$33,3),H39),0) -> 0 | I39: =IF(A39,IF(D39,MIN('SE4X Production'!$E$34,3),I39),0) -> 0 | J39: =IF(A39,IF(D39,MIN('SE4X Production'!$E$35,7),J39),1) -> 1 | K39: =IF(A39,IF(D39,IF(J39>=6,"+",""),K39),"") | L39: =IF(A39,IF(D39,IF('SE4X Production'!$E$47>=1," Shield Projector",""),L39),"") | M39: =IF(A39,IF(D39,IF('SE4X Production'!$E$47>=1,'SE4X Production'!$E$56,""),M39),"")
A40: FALSE | D40: FALSE | F40: DN #2 | G40: =IF(A40,IF(D40,MIN('SE4X Production'!$E$32,3),G40),0) -> 0 | H40: =IF(A40,IF(D40,MIN('SE4X Production'!$E$33,3),H40),0) -> 0 | I40: =IF(A40,IF(D40,MIN('SE4X Production'!$E$34,3),I40),0) -> 0 | J40: =IF(A40,IF(D40,MIN('SE4X Production'!$E$35,7),J40),1) -> 1 | K40: =IF(A40,IF(D40,IF(J40>=6,"+",""),K40),"") | L40: =IF(A40,IF(D40,IF('SE4X Production'!$E$47>=1," Shield Projector",""),L40),"") | M40: =IF(A40,IF(D40,IF('SE4X Production'!$E$47>=1,'SE4X Production'!$E$56,""),M40),"")
...
